{
  "nbformat": 4,
  "nbformat_minor": 0,
  "metadata": {
    "colab": {
      "provenance": [],
      "authorship_tag": "ABX9TyNz4sWCYz863XSVQOlC8MAh",
      "include_colab_link": true
    },
    "kernelspec": {
      "name": "python3",
      "display_name": "Python 3"
    },
    "language_info": {
      "name": "python"
    }
  },
  "cells": [
    {
      "cell_type": "markdown",
      "metadata": {
        "id": "view-in-github",
        "colab_type": "text"
      },
      "source": [
        "<a href=\"https://colab.research.google.com/github/depak-kumar/heart_disease_predict/blob/main/crop_recomender.ipynb\" target=\"_parent\"><img src=\"https://colab.research.google.com/assets/colab-badge.svg\" alt=\"Open In Colab\"/></a>"
      ]
    },
    {
      "cell_type": "code",
      "execution_count": 6,
      "metadata": {
        "colab": {
          "base_uri": "https://localhost:8080/"
        },
        "id": "a6Q8zh9Xk7bz",
        "outputId": "5c947087-3ef5-42af-eebb-02285b3ca540"
      },
      "outputs": [
        {
          "output_type": "stream",
          "name": "stdout",
          "text": [
            "Requirement already satisfied: streamlit in /usr/local/lib/python3.10/dist-packages (1.26.0)\n",
            "Requirement already satisfied: altair<6,>=4.0 in /usr/local/lib/python3.10/dist-packages (from streamlit) (4.2.2)\n",
            "Requirement already satisfied: blinker<2,>=1.0.0 in /usr/lib/python3/dist-packages (from streamlit) (1.4)\n",
            "Requirement already satisfied: cachetools<6,>=4.0 in /usr/local/lib/python3.10/dist-packages (from streamlit) (5.3.1)\n",
            "Requirement already satisfied: click<9,>=7.0 in /usr/local/lib/python3.10/dist-packages (from streamlit) (8.1.7)\n",
            "Requirement already satisfied: importlib-metadata<7,>=1.4 in /usr/local/lib/python3.10/dist-packages (from streamlit) (6.8.0)\n",
            "Requirement already satisfied: numpy<2,>=1.19.3 in /usr/local/lib/python3.10/dist-packages (from streamlit) (1.23.5)\n",
            "Requirement already satisfied: packaging<24,>=16.8 in /usr/local/lib/python3.10/dist-packages (from streamlit) (23.1)\n",
            "Requirement already satisfied: pandas<3,>=1.3.0 in /usr/local/lib/python3.10/dist-packages (from streamlit) (1.5.3)\n",
            "Requirement already satisfied: pillow<10,>=7.1.0 in /usr/local/lib/python3.10/dist-packages (from streamlit) (9.4.0)\n",
            "Requirement already satisfied: protobuf<5,>=3.20 in /usr/local/lib/python3.10/dist-packages (from streamlit) (3.20.3)\n",
            "Requirement already satisfied: pyarrow>=6.0 in /usr/local/lib/python3.10/dist-packages (from streamlit) (9.0.0)\n",
            "Requirement already satisfied: pympler<2,>=0.9 in /usr/local/lib/python3.10/dist-packages (from streamlit) (1.0.1)\n",
            "Requirement already satisfied: python-dateutil<3,>=2.7.3 in /usr/local/lib/python3.10/dist-packages (from streamlit) (2.8.2)\n",
            "Requirement already satisfied: requests<3,>=2.18 in /usr/local/lib/python3.10/dist-packages (from streamlit) (2.31.0)\n",
            "Requirement already satisfied: rich<14,>=10.14.0 in /usr/local/lib/python3.10/dist-packages (from streamlit) (13.5.2)\n",
            "Requirement already satisfied: tenacity<9,>=8.1.0 in /usr/local/lib/python3.10/dist-packages (from streamlit) (8.2.3)\n",
            "Requirement already satisfied: toml<2,>=0.10.1 in /usr/local/lib/python3.10/dist-packages (from streamlit) (0.10.2)\n",
            "Requirement already satisfied: typing-extensions<5,>=4.1.0 in /usr/local/lib/python3.10/dist-packages (from streamlit) (4.7.1)\n",
            "Requirement already satisfied: tzlocal<5,>=1.1 in /usr/local/lib/python3.10/dist-packages (from streamlit) (4.3.1)\n",
            "Requirement already satisfied: validators<1,>=0.2 in /usr/local/lib/python3.10/dist-packages (from streamlit) (0.21.2)\n",
            "Requirement already satisfied: gitpython!=3.1.19,<4,>=3.0.7 in /usr/local/lib/python3.10/dist-packages (from streamlit) (3.1.32)\n",
            "Requirement already satisfied: pydeck<1,>=0.8 in /usr/local/lib/python3.10/dist-packages (from streamlit) (0.8.0)\n",
            "Requirement already satisfied: tornado<7,>=6.0.3 in /usr/local/lib/python3.10/dist-packages (from streamlit) (6.3.2)\n",
            "Requirement already satisfied: watchdog>=2.1.5 in /usr/local/lib/python3.10/dist-packages (from streamlit) (3.0.0)\n",
            "Requirement already satisfied: entrypoints in /usr/local/lib/python3.10/dist-packages (from altair<6,>=4.0->streamlit) (0.4)\n",
            "Requirement already satisfied: jinja2 in /usr/local/lib/python3.10/dist-packages (from altair<6,>=4.0->streamlit) (3.1.2)\n",
            "Requirement already satisfied: jsonschema>=3.0 in /usr/local/lib/python3.10/dist-packages (from altair<6,>=4.0->streamlit) (4.19.0)\n",
            "Requirement already satisfied: toolz in /usr/local/lib/python3.10/dist-packages (from altair<6,>=4.0->streamlit) (0.12.0)\n",
            "Requirement already satisfied: gitdb<5,>=4.0.1 in /usr/local/lib/python3.10/dist-packages (from gitpython!=3.1.19,<4,>=3.0.7->streamlit) (4.0.10)\n",
            "Requirement already satisfied: zipp>=0.5 in /usr/local/lib/python3.10/dist-packages (from importlib-metadata<7,>=1.4->streamlit) (3.16.2)\n",
            "Requirement already satisfied: pytz>=2020.1 in /usr/local/lib/python3.10/dist-packages (from pandas<3,>=1.3.0->streamlit) (2023.3)\n",
            "Requirement already satisfied: six>=1.5 in /usr/local/lib/python3.10/dist-packages (from python-dateutil<3,>=2.7.3->streamlit) (1.16.0)\n",
            "Requirement already satisfied: charset-normalizer<4,>=2 in /usr/local/lib/python3.10/dist-packages (from requests<3,>=2.18->streamlit) (3.2.0)\n",
            "Requirement already satisfied: idna<4,>=2.5 in /usr/local/lib/python3.10/dist-packages (from requests<3,>=2.18->streamlit) (3.4)\n",
            "Requirement already satisfied: urllib3<3,>=1.21.1 in /usr/local/lib/python3.10/dist-packages (from requests<3,>=2.18->streamlit) (2.0.4)\n",
            "Requirement already satisfied: certifi>=2017.4.17 in /usr/local/lib/python3.10/dist-packages (from requests<3,>=2.18->streamlit) (2023.7.22)\n",
            "Requirement already satisfied: markdown-it-py>=2.2.0 in /usr/local/lib/python3.10/dist-packages (from rich<14,>=10.14.0->streamlit) (3.0.0)\n",
            "Requirement already satisfied: pygments<3.0.0,>=2.13.0 in /usr/local/lib/python3.10/dist-packages (from rich<14,>=10.14.0->streamlit) (2.16.1)\n",
            "Requirement already satisfied: pytz-deprecation-shim in /usr/local/lib/python3.10/dist-packages (from tzlocal<5,>=1.1->streamlit) (0.1.0.post0)\n",
            "Requirement already satisfied: smmap<6,>=3.0.1 in /usr/local/lib/python3.10/dist-packages (from gitdb<5,>=4.0.1->gitpython!=3.1.19,<4,>=3.0.7->streamlit) (5.0.0)\n",
            "Requirement already satisfied: MarkupSafe>=2.0 in /usr/local/lib/python3.10/dist-packages (from jinja2->altair<6,>=4.0->streamlit) (2.1.3)\n",
            "Requirement already satisfied: attrs>=22.2.0 in /usr/local/lib/python3.10/dist-packages (from jsonschema>=3.0->altair<6,>=4.0->streamlit) (23.1.0)\n",
            "Requirement already satisfied: jsonschema-specifications>=2023.03.6 in /usr/local/lib/python3.10/dist-packages (from jsonschema>=3.0->altair<6,>=4.0->streamlit) (2023.7.1)\n",
            "Requirement already satisfied: referencing>=0.28.4 in /usr/local/lib/python3.10/dist-packages (from jsonschema>=3.0->altair<6,>=4.0->streamlit) (0.30.2)\n",
            "Requirement already satisfied: rpds-py>=0.7.1 in /usr/local/lib/python3.10/dist-packages (from jsonschema>=3.0->altair<6,>=4.0->streamlit) (0.9.2)\n",
            "Requirement already satisfied: mdurl~=0.1 in /usr/local/lib/python3.10/dist-packages (from markdown-it-py>=2.2.0->rich<14,>=10.14.0->streamlit) (0.1.2)\n",
            "Requirement already satisfied: tzdata in /usr/local/lib/python3.10/dist-packages (from pytz-deprecation-shim->tzlocal<5,>=1.1->streamlit) (2023.3)\n"
          ]
        }
      ],
      "source": [
        "!pip install streamlit\n",
        "import pandas as pd\n",
        "import numpy as np\n",
        "import pickle"
      ]
    },
    {
      "cell_type": "code",
      "source": [
        "from google.colab import drive\n",
        "drive.mount('/content/drive')"
      ],
      "metadata": {
        "colab": {
          "base_uri": "https://localhost:8080/"
        },
        "id": "GeE3n0mDorKo",
        "outputId": "ea35bb49-8168-4c87-c8bf-359311206266"
      },
      "execution_count": null,
      "outputs": [
        {
          "output_type": "stream",
          "name": "stdout",
          "text": [
            "Mounted at /content/drive\n"
          ]
        }
      ]
    },
    {
      "cell_type": "code",
      "source": [
        "! streamlit run /content/drive/MyDrive/app4.py & npx localtunnel --port 8501"
      ],
      "metadata": {
        "colab": {
          "base_uri": "https://localhost:8080/"
        },
        "id": "J_ro6KQ_oxeY",
        "outputId": "2968dc78-6b1f-4908-cbca-998c746f472b"
      },
      "execution_count": 5,
      "outputs": [
        {
          "output_type": "stream",
          "name": "stdout",
          "text": [
            "[#.................] - fetchMetadata: sill resolveWithNewModule follow-redirect\u001b[0m\u001b[K\n",
            "Collecting usage statistics. To deactivate, set browser.gatherUsageStats to False.\n",
            "\u001b[0m\n",
            "\u001b[0m\n",
            "\u001b[34m\u001b[1m  You can now view your Streamlit app in your browser.\u001b[0m\n",
            "\u001b[0m\n",
            "\u001b[34m  Network URL: \u001b[0m\u001b[1mhttp://172.28.0.12:8501\u001b[0m\n",
            "\u001b[34m  External URL: \u001b[0m\u001b[1mhttp://34.86.170.67:8501\u001b[0m\n",
            "\u001b[0m\n",
            "\u001b[K\u001b[?25hnpx: installed 22 in 3.498s\n",
            "your url is: https://evil-glasses-scream.loca.lt\n",
            "2023-08-30 14:29:17.900488: I tensorflow/core/platform/cpu_feature_guard.cc:182] This TensorFlow binary is optimized to use available CPU instructions in performance-critical operations.\n",
            "To enable the following instructions: AVX2 FMA, in other operations, rebuild TensorFlow with the appropriate compiler flags.\n",
            "2023-08-30 14:29:18.992857: W tensorflow/compiler/tf2tensorrt/utils/py_utils.cc:38] TF-TRT Warning: Could not find TensorRT\n",
            "2023-08-30 14:31:06.908 Uncaught app exception\n",
            "Traceback (most recent call last):\n",
            "  File \"/usr/local/lib/python3.10/dist-packages/streamlit/runtime/scriptrunner/script_runner.py\", line 552, in _run_script\n",
            "    exec(code, module.__dict__)\n",
            "  File \"/content/drive/MyDrive/app4.py\", line 111, in <module>\n",
            "    uploaded_image1 = st.file_uploader(\"Choose an image...\", type=[\"jpg\", \"png\", \"jpeg\"])\n",
            "  File \"/usr/local/lib/python3.10/dist-packages/streamlit/runtime/metrics_util.py\", line 358, in wrapped_func\n",
            "    result = non_optional_func(*args, **kwargs)\n",
            "  File \"/usr/local/lib/python3.10/dist-packages/streamlit/elements/widgets/file_uploader.py\", line 365, in file_uploader\n",
            "    return self._file_uploader(\n",
            "  File \"/usr/local/lib/python3.10/dist-packages/streamlit/elements/widgets/file_uploader.py\", line 451, in _file_uploader\n",
            "    widget_state = register_widget(\n",
            "  File \"/usr/local/lib/python3.10/dist-packages/streamlit/runtime/state/widgets.py\", line 161, in register_widget\n",
            "    return register_widget_from_metadata(metadata, ctx, widget_func_name, element_type)\n",
            "  File \"/usr/local/lib/python3.10/dist-packages/streamlit/runtime/state/widgets.py\", line 206, in register_widget_from_metadata\n",
            "    raise DuplicateWidgetID(\n",
            "streamlit.errors.DuplicateWidgetID: There are multiple identical `st.file_uploader` widgets with the\n",
            "same generated key.\n",
            "\n",
            "When a widget is created, it's assigned an internal key based on\n",
            "its structure. Multiple widgets with an identical structure will\n",
            "result in the same internal key, which causes this error.\n",
            "\n",
            "To fix this error, please pass a unique `key` argument to\n",
            "`st.file_uploader`.\n",
            "2023-08-30 14:31:16.516 Uncaught app exception\n",
            "Traceback (most recent call last):\n",
            "  File \"/usr/local/lib/python3.10/dist-packages/streamlit/runtime/scriptrunner/script_runner.py\", line 552, in _run_script\n",
            "    exec(code, module.__dict__)\n",
            "  File \"/content/drive/MyDrive/app4.py\", line 111, in <module>\n",
            "    uploaded_image1 = st.file_uploader(\"Choose an image...\", type=[\"jpg\", \"png\", \"jpeg\"])\n",
            "  File \"/usr/local/lib/python3.10/dist-packages/streamlit/runtime/metrics_util.py\", line 358, in wrapped_func\n",
            "    result = non_optional_func(*args, **kwargs)\n",
            "  File \"/usr/local/lib/python3.10/dist-packages/streamlit/elements/widgets/file_uploader.py\", line 365, in file_uploader\n",
            "    return self._file_uploader(\n",
            "  File \"/usr/local/lib/python3.10/dist-packages/streamlit/elements/widgets/file_uploader.py\", line 451, in _file_uploader\n",
            "    widget_state = register_widget(\n",
            "  File \"/usr/local/lib/python3.10/dist-packages/streamlit/runtime/state/widgets.py\", line 161, in register_widget\n",
            "    return register_widget_from_metadata(metadata, ctx, widget_func_name, element_type)\n",
            "  File \"/usr/local/lib/python3.10/dist-packages/streamlit/runtime/state/widgets.py\", line 206, in register_widget_from_metadata\n",
            "    raise DuplicateWidgetID(\n",
            "streamlit.errors.DuplicateWidgetID: There are multiple identical `st.file_uploader` widgets with the\n",
            "same generated key.\n",
            "\n",
            "When a widget is created, it's assigned an internal key based on\n",
            "its structure. Multiple widgets with an identical structure will\n",
            "result in the same internal key, which causes this error.\n",
            "\n",
            "To fix this error, please pass a unique `key` argument to\n",
            "`st.file_uploader`.\n",
            "2023-08-30 14:31:29.786 Uncaught app exception\n",
            "Traceback (most recent call last):\n",
            "  File \"/usr/local/lib/python3.10/dist-packages/streamlit/runtime/scriptrunner/script_runner.py\", line 552, in _run_script\n",
            "    exec(code, module.__dict__)\n",
            "  File \"/content/drive/MyDrive/app4.py\", line 111, in <module>\n",
            "    uploaded_image1 = st.file_uploader(\"Choose an image...\", type=[\"jpg\", \"png\", \"jpeg\"])\n",
            "  File \"/usr/local/lib/python3.10/dist-packages/streamlit/runtime/metrics_util.py\", line 358, in wrapped_func\n",
            "    result = non_optional_func(*args, **kwargs)\n",
            "  File \"/usr/local/lib/python3.10/dist-packages/streamlit/elements/widgets/file_uploader.py\", line 365, in file_uploader\n",
            "    return self._file_uploader(\n",
            "  File \"/usr/local/lib/python3.10/dist-packages/streamlit/elements/widgets/file_uploader.py\", line 451, in _file_uploader\n",
            "    widget_state = register_widget(\n",
            "  File \"/usr/local/lib/python3.10/dist-packages/streamlit/runtime/state/widgets.py\", line 161, in register_widget\n",
            "    return register_widget_from_metadata(metadata, ctx, widget_func_name, element_type)\n",
            "  File \"/usr/local/lib/python3.10/dist-packages/streamlit/runtime/state/widgets.py\", line 206, in register_widget_from_metadata\n",
            "    raise DuplicateWidgetID(\n",
            "streamlit.errors.DuplicateWidgetID: There are multiple identical `st.file_uploader` widgets with the\n",
            "same generated key.\n",
            "\n",
            "When a widget is created, it's assigned an internal key based on\n",
            "its structure. Multiple widgets with an identical structure will\n",
            "result in the same internal key, which causes this error.\n",
            "\n",
            "To fix this error, please pass a unique `key` argument to\n",
            "`st.file_uploader`.\n",
            "2023-08-30 14:32:20.955 Uncaught app exception\n",
            "Traceback (most recent call last):\n",
            "  File \"/usr/local/lib/python3.10/dist-packages/streamlit/runtime/scriptrunner/script_runner.py\", line 552, in _run_script\n",
            "    exec(code, module.__dict__)\n",
            "  File \"/content/drive/MyDrive/app4.py\", line 111, in <module>\n",
            "    uploaded_image1 = st.file_uploader(\"Choose an image...\", type=[\"jpg\", \"png\", \"jpeg\"])\n",
            "  File \"/usr/local/lib/python3.10/dist-packages/streamlit/runtime/metrics_util.py\", line 358, in wrapped_func\n",
            "    result = non_optional_func(*args, **kwargs)\n",
            "  File \"/usr/local/lib/python3.10/dist-packages/streamlit/elements/widgets/file_uploader.py\", line 365, in file_uploader\n",
            "    return self._file_uploader(\n",
            "  File \"/usr/local/lib/python3.10/dist-packages/streamlit/elements/widgets/file_uploader.py\", line 451, in _file_uploader\n",
            "    widget_state = register_widget(\n",
            "  File \"/usr/local/lib/python3.10/dist-packages/streamlit/runtime/state/widgets.py\", line 161, in register_widget\n",
            "    return register_widget_from_metadata(metadata, ctx, widget_func_name, element_type)\n",
            "  File \"/usr/local/lib/python3.10/dist-packages/streamlit/runtime/state/widgets.py\", line 206, in register_widget_from_metadata\n",
            "    raise DuplicateWidgetID(\n",
            "streamlit.errors.DuplicateWidgetID: There are multiple identical `st.file_uploader` widgets with the\n",
            "same generated key.\n",
            "\n",
            "When a widget is created, it's assigned an internal key based on\n",
            "its structure. Multiple widgets with an identical structure will\n",
            "result in the same internal key, which causes this error.\n",
            "\n",
            "To fix this error, please pass a unique `key` argument to\n",
            "`st.file_uploader`.\n",
            "2023-08-30 14:32:37.192 Uncaught app exception\n",
            "Traceback (most recent call last):\n",
            "  File \"/usr/local/lib/python3.10/dist-packages/streamlit/runtime/scriptrunner/script_runner.py\", line 552, in _run_script\n",
            "    exec(code, module.__dict__)\n",
            "  File \"/content/drive/MyDrive/app4.py\", line 111, in <module>\n",
            "    uploaded_image1 = st.file_uploader(\"Choose an image...\", type=[\"jpg\", \"png\", \"jpeg\"])\n",
            "  File \"/usr/local/lib/python3.10/dist-packages/streamlit/runtime/metrics_util.py\", line 358, in wrapped_func\n",
            "    result = non_optional_func(*args, **kwargs)\n",
            "  File \"/usr/local/lib/python3.10/dist-packages/streamlit/elements/widgets/file_uploader.py\", line 365, in file_uploader\n",
            "    return self._file_uploader(\n",
            "  File \"/usr/local/lib/python3.10/dist-packages/streamlit/elements/widgets/file_uploader.py\", line 451, in _file_uploader\n",
            "    widget_state = register_widget(\n",
            "  File \"/usr/local/lib/python3.10/dist-packages/streamlit/runtime/state/widgets.py\", line 161, in register_widget\n",
            "    return register_widget_from_metadata(metadata, ctx, widget_func_name, element_type)\n",
            "  File \"/usr/local/lib/python3.10/dist-packages/streamlit/runtime/state/widgets.py\", line 206, in register_widget_from_metadata\n",
            "    raise DuplicateWidgetID(\n",
            "streamlit.errors.DuplicateWidgetID: There are multiple identical `st.file_uploader` widgets with the\n",
            "same generated key.\n",
            "\n",
            "When a widget is created, it's assigned an internal key based on\n",
            "its structure. Multiple widgets with an identical structure will\n",
            "result in the same internal key, which causes this error.\n",
            "\n",
            "To fix this error, please pass a unique `key` argument to\n",
            "`st.file_uploader`.\n",
            "2023-08-30 14:32:44.033 Uncaught app exception\n",
            "Traceback (most recent call last):\n",
            "  File \"/usr/local/lib/python3.10/dist-packages/streamlit/runtime/scriptrunner/script_runner.py\", line 552, in _run_script\n",
            "    exec(code, module.__dict__)\n",
            "  File \"/content/drive/MyDrive/app4.py\", line 111, in <module>\n",
            "    uploaded_image1 = st.file_uploader(\"Choose an image...\", type=[\"jpg\", \"png\", \"jpeg\"])\n",
            "  File \"/usr/local/lib/python3.10/dist-packages/streamlit/runtime/metrics_util.py\", line 358, in wrapped_func\n",
            "    result = non_optional_func(*args, **kwargs)\n",
            "  File \"/usr/local/lib/python3.10/dist-packages/streamlit/elements/widgets/file_uploader.py\", line 365, in file_uploader\n",
            "    return self._file_uploader(\n",
            "  File \"/usr/local/lib/python3.10/dist-packages/streamlit/elements/widgets/file_uploader.py\", line 451, in _file_uploader\n",
            "    widget_state = register_widget(\n",
            "  File \"/usr/local/lib/python3.10/dist-packages/streamlit/runtime/state/widgets.py\", line 161, in register_widget\n",
            "    return register_widget_from_metadata(metadata, ctx, widget_func_name, element_type)\n",
            "  File \"/usr/local/lib/python3.10/dist-packages/streamlit/runtime/state/widgets.py\", line 206, in register_widget_from_metadata\n",
            "    raise DuplicateWidgetID(\n",
            "streamlit.errors.DuplicateWidgetID: There are multiple identical `st.file_uploader` widgets with the\n",
            "same generated key.\n",
            "\n",
            "When a widget is created, it's assigned an internal key based on\n",
            "its structure. Multiple widgets with an identical structure will\n",
            "result in the same internal key, which causes this error.\n",
            "\n",
            "To fix this error, please pass a unique `key` argument to\n",
            "`st.file_uploader`.\n",
            "2023-08-30 14:32:53.435 Uncaught app exception\n",
            "Traceback (most recent call last):\n",
            "  File \"/usr/local/lib/python3.10/dist-packages/streamlit/runtime/scriptrunner/script_runner.py\", line 552, in _run_script\n",
            "    exec(code, module.__dict__)\n",
            "  File \"/content/drive/MyDrive/app4.py\", line 111, in <module>\n",
            "    uploaded_image1 = st.file_uploader(\"Choose an image...\", type=[\"jpg\", \"png\", \"jpeg\"])\n",
            "  File \"/usr/local/lib/python3.10/dist-packages/streamlit/runtime/metrics_util.py\", line 358, in wrapped_func\n",
            "    result = non_optional_func(*args, **kwargs)\n",
            "  File \"/usr/local/lib/python3.10/dist-packages/streamlit/elements/widgets/file_uploader.py\", line 365, in file_uploader\n",
            "    return self._file_uploader(\n",
            "  File \"/usr/local/lib/python3.10/dist-packages/streamlit/elements/widgets/file_uploader.py\", line 451, in _file_uploader\n",
            "    widget_state = register_widget(\n",
            "  File \"/usr/local/lib/python3.10/dist-packages/streamlit/runtime/state/widgets.py\", line 161, in register_widget\n",
            "    return register_widget_from_metadata(metadata, ctx, widget_func_name, element_type)\n",
            "  File \"/usr/local/lib/python3.10/dist-packages/streamlit/runtime/state/widgets.py\", line 206, in register_widget_from_metadata\n",
            "    raise DuplicateWidgetID(\n",
            "streamlit.errors.DuplicateWidgetID: There are multiple identical `st.file_uploader` widgets with the\n",
            "same generated key.\n",
            "\n",
            "When a widget is created, it's assigned an internal key based on\n",
            "its structure. Multiple widgets with an identical structure will\n",
            "result in the same internal key, which causes this error.\n",
            "\n",
            "To fix this error, please pass a unique `key` argument to\n",
            "`st.file_uploader`.\n",
            "2023-08-30 14:33:05.437 Uncaught app exception\n",
            "Traceback (most recent call last):\n",
            "  File \"/usr/local/lib/python3.10/dist-packages/streamlit/runtime/scriptrunner/script_runner.py\", line 552, in _run_script\n",
            "    exec(code, module.__dict__)\n",
            "  File \"/content/drive/MyDrive/app4.py\", line 111, in <module>\n",
            "    uploaded_image1 = st.file_uploader(\"Choose an image...\", type=[\"jpg\", \"png\", \"jpeg\"])\n",
            "  File \"/usr/local/lib/python3.10/dist-packages/streamlit/runtime/metrics_util.py\", line 358, in wrapped_func\n",
            "    result = non_optional_func(*args, **kwargs)\n",
            "  File \"/usr/local/lib/python3.10/dist-packages/streamlit/elements/widgets/file_uploader.py\", line 365, in file_uploader\n",
            "    return self._file_uploader(\n",
            "  File \"/usr/local/lib/python3.10/dist-packages/streamlit/elements/widgets/file_uploader.py\", line 451, in _file_uploader\n",
            "    widget_state = register_widget(\n",
            "  File \"/usr/local/lib/python3.10/dist-packages/streamlit/runtime/state/widgets.py\", line 161, in register_widget\n",
            "    return register_widget_from_metadata(metadata, ctx, widget_func_name, element_type)\n",
            "  File \"/usr/local/lib/python3.10/dist-packages/streamlit/runtime/state/widgets.py\", line 206, in register_widget_from_metadata\n",
            "    raise DuplicateWidgetID(\n",
            "streamlit.errors.DuplicateWidgetID: There are multiple identical `st.file_uploader` widgets with the\n",
            "same generated key.\n",
            "\n",
            "When a widget is created, it's assigned an internal key based on\n",
            "its structure. Multiple widgets with an identical structure will\n",
            "result in the same internal key, which causes this error.\n",
            "\n",
            "To fix this error, please pass a unique `key` argument to\n",
            "`st.file_uploader`.\n",
            "2023-08-30 14:33:14.823 Uncaught app exception\n",
            "Traceback (most recent call last):\n",
            "  File \"/usr/local/lib/python3.10/dist-packages/streamlit/runtime/scriptrunner/script_runner.py\", line 552, in _run_script\n",
            "    exec(code, module.__dict__)\n",
            "  File \"/content/drive/MyDrive/app4.py\", line 111, in <module>\n",
            "    uploaded_image1 = st.file_uploader(\"Choose an image...\", type=[\"jpg\", \"png\", \"jpeg\"])\n",
            "  File \"/usr/local/lib/python3.10/dist-packages/streamlit/runtime/metrics_util.py\", line 358, in wrapped_func\n",
            "    result = non_optional_func(*args, **kwargs)\n",
            "  File \"/usr/local/lib/python3.10/dist-packages/streamlit/elements/widgets/file_uploader.py\", line 365, in file_uploader\n",
            "    return self._file_uploader(\n",
            "  File \"/usr/local/lib/python3.10/dist-packages/streamlit/elements/widgets/file_uploader.py\", line 451, in _file_uploader\n",
            "    widget_state = register_widget(\n",
            "  File \"/usr/local/lib/python3.10/dist-packages/streamlit/runtime/state/widgets.py\", line 161, in register_widget\n",
            "    return register_widget_from_metadata(metadata, ctx, widget_func_name, element_type)\n",
            "  File \"/usr/local/lib/python3.10/dist-packages/streamlit/runtime/state/widgets.py\", line 206, in register_widget_from_metadata\n",
            "    raise DuplicateWidgetID(\n",
            "streamlit.errors.DuplicateWidgetID: There are multiple identical `st.file_uploader` widgets with the\n",
            "same generated key.\n",
            "\n",
            "When a widget is created, it's assigned an internal key based on\n",
            "its structure. Multiple widgets with an identical structure will\n",
            "result in the same internal key, which causes this error.\n",
            "\n",
            "To fix this error, please pass a unique `key` argument to\n",
            "`st.file_uploader`.\n",
            "2023-08-30 14:33:23.479 Uncaught app exception\n",
            "Traceback (most recent call last):\n",
            "  File \"/usr/local/lib/python3.10/dist-packages/streamlit/runtime/scriptrunner/script_runner.py\", line 552, in _run_script\n",
            "    exec(code, module.__dict__)\n",
            "  File \"/content/drive/MyDrive/app4.py\", line 111, in <module>\n",
            "    uploaded_image1 = st.file_uploader(\"Choose an image...\", type=[\"jpg\", \"png\", \"jpeg\"])\n",
            "  File \"/usr/local/lib/python3.10/dist-packages/streamlit/runtime/metrics_util.py\", line 358, in wrapped_func\n",
            "    result = non_optional_func(*args, **kwargs)\n",
            "  File \"/usr/local/lib/python3.10/dist-packages/streamlit/elements/widgets/file_uploader.py\", line 365, in file_uploader\n",
            "    return self._file_uploader(\n",
            "  File \"/usr/local/lib/python3.10/dist-packages/streamlit/elements/widgets/file_uploader.py\", line 451, in _file_uploader\n",
            "    widget_state = register_widget(\n",
            "  File \"/usr/local/lib/python3.10/dist-packages/streamlit/runtime/state/widgets.py\", line 161, in register_widget\n",
            "    return register_widget_from_metadata(metadata, ctx, widget_func_name, element_type)\n",
            "  File \"/usr/local/lib/python3.10/dist-packages/streamlit/runtime/state/widgets.py\", line 206, in register_widget_from_metadata\n",
            "    raise DuplicateWidgetID(\n",
            "streamlit.errors.DuplicateWidgetID: There are multiple identical `st.file_uploader` widgets with the\n",
            "same generated key.\n",
            "\n",
            "When a widget is created, it's assigned an internal key based on\n",
            "its structure. Multiple widgets with an identical structure will\n",
            "result in the same internal key, which causes this error.\n",
            "\n",
            "To fix this error, please pass a unique `key` argument to\n",
            "`st.file_uploader`.\n",
            "2023-08-30 14:33:49.632 Uncaught app exception\n",
            "Traceback (most recent call last):\n",
            "  File \"/usr/local/lib/python3.10/dist-packages/streamlit/runtime/scriptrunner/script_runner.py\", line 552, in _run_script\n",
            "    exec(code, module.__dict__)\n",
            "  File \"/content/drive/MyDrive/app4.py\", line 111, in <module>\n",
            "    uploaded_image1 = st.file_uploader(\"Choose an image...\", type=[\"jpg\", \"png\", \"jpeg\"])\n",
            "  File \"/usr/local/lib/python3.10/dist-packages/streamlit/runtime/metrics_util.py\", line 358, in wrapped_func\n",
            "    result = non_optional_func(*args, **kwargs)\n",
            "  File \"/usr/local/lib/python3.10/dist-packages/streamlit/elements/widgets/file_uploader.py\", line 365, in file_uploader\n",
            "    return self._file_uploader(\n",
            "  File \"/usr/local/lib/python3.10/dist-packages/streamlit/elements/widgets/file_uploader.py\", line 451, in _file_uploader\n",
            "    widget_state = register_widget(\n",
            "  File \"/usr/local/lib/python3.10/dist-packages/streamlit/runtime/state/widgets.py\", line 161, in register_widget\n",
            "    return register_widget_from_metadata(metadata, ctx, widget_func_name, element_type)\n",
            "  File \"/usr/local/lib/python3.10/dist-packages/streamlit/runtime/state/widgets.py\", line 206, in register_widget_from_metadata\n",
            "    raise DuplicateWidgetID(\n",
            "streamlit.errors.DuplicateWidgetID: There are multiple identical `st.file_uploader` widgets with the\n",
            "same generated key.\n",
            "\n",
            "When a widget is created, it's assigned an internal key based on\n",
            "its structure. Multiple widgets with an identical structure will\n",
            "result in the same internal key, which causes this error.\n",
            "\n",
            "To fix this error, please pass a unique `key` argument to\n",
            "`st.file_uploader`.\n",
            "2023-08-30 14:34:00.601 Uncaught app exception\n",
            "Traceback (most recent call last):\n",
            "  File \"/usr/local/lib/python3.10/dist-packages/streamlit/runtime/scriptrunner/script_runner.py\", line 552, in _run_script\n",
            "    exec(code, module.__dict__)\n",
            "  File \"/content/drive/MyDrive/app4.py\", line 111, in <module>\n",
            "    uploaded_image1 = st.file_uploader(\"Choose an image...\", type=[\"jpg\", \"png\", \"jpeg\"])\n",
            "  File \"/usr/local/lib/python3.10/dist-packages/streamlit/runtime/metrics_util.py\", line 358, in wrapped_func\n",
            "    result = non_optional_func(*args, **kwargs)\n",
            "  File \"/usr/local/lib/python3.10/dist-packages/streamlit/elements/widgets/file_uploader.py\", line 365, in file_uploader\n",
            "    return self._file_uploader(\n",
            "  File \"/usr/local/lib/python3.10/dist-packages/streamlit/elements/widgets/file_uploader.py\", line 451, in _file_uploader\n",
            "    widget_state = register_widget(\n",
            "  File \"/usr/local/lib/python3.10/dist-packages/streamlit/runtime/state/widgets.py\", line 161, in register_widget\n",
            "    return register_widget_from_metadata(metadata, ctx, widget_func_name, element_type)\n",
            "  File \"/usr/local/lib/python3.10/dist-packages/streamlit/runtime/state/widgets.py\", line 206, in register_widget_from_metadata\n",
            "    raise DuplicateWidgetID(\n",
            "streamlit.errors.DuplicateWidgetID: There are multiple identical `st.file_uploader` widgets with the\n",
            "same generated key.\n",
            "\n",
            "When a widget is created, it's assigned an internal key based on\n",
            "its structure. Multiple widgets with an identical structure will\n",
            "result in the same internal key, which causes this error.\n",
            "\n",
            "To fix this error, please pass a unique `key` argument to\n",
            "`st.file_uploader`.\n",
            "2023-08-30 14:34:07.192 Uncaught app exception\n",
            "Traceback (most recent call last):\n",
            "  File \"/usr/local/lib/python3.10/dist-packages/streamlit/runtime/scriptrunner/script_runner.py\", line 552, in _run_script\n",
            "    exec(code, module.__dict__)\n",
            "  File \"/content/drive/MyDrive/app4.py\", line 111, in <module>\n",
            "    uploaded_image1 = st.file_uploader(\"Choose an image...\", type=[\"jpg\", \"png\", \"jpeg\"])\n",
            "  File \"/usr/local/lib/python3.10/dist-packages/streamlit/runtime/metrics_util.py\", line 358, in wrapped_func\n",
            "    result = non_optional_func(*args, **kwargs)\n",
            "  File \"/usr/local/lib/python3.10/dist-packages/streamlit/elements/widgets/file_uploader.py\", line 365, in file_uploader\n",
            "    return self._file_uploader(\n",
            "  File \"/usr/local/lib/python3.10/dist-packages/streamlit/elements/widgets/file_uploader.py\", line 451, in _file_uploader\n",
            "    widget_state = register_widget(\n",
            "  File \"/usr/local/lib/python3.10/dist-packages/streamlit/runtime/state/widgets.py\", line 161, in register_widget\n",
            "    return register_widget_from_metadata(metadata, ctx, widget_func_name, element_type)\n",
            "  File \"/usr/local/lib/python3.10/dist-packages/streamlit/runtime/state/widgets.py\", line 206, in register_widget_from_metadata\n",
            "    raise DuplicateWidgetID(\n",
            "streamlit.errors.DuplicateWidgetID: There are multiple identical `st.file_uploader` widgets with the\n",
            "same generated key.\n",
            "\n",
            "When a widget is created, it's assigned an internal key based on\n",
            "its structure. Multiple widgets with an identical structure will\n",
            "result in the same internal key, which causes this error.\n",
            "\n",
            "To fix this error, please pass a unique `key` argument to\n",
            "`st.file_uploader`.\n",
            "2023-08-30 14:34:17.728 Uncaught app exception\n",
            "Traceback (most recent call last):\n",
            "  File \"/usr/local/lib/python3.10/dist-packages/streamlit/runtime/scriptrunner/script_runner.py\", line 552, in _run_script\n",
            "    exec(code, module.__dict__)\n",
            "  File \"/content/drive/MyDrive/app4.py\", line 111, in <module>\n",
            "    uploaded_image1 = st.file_uploader(\"Choose an image...\", type=[\"jpg\", \"png\", \"jpeg\"])\n",
            "  File \"/usr/local/lib/python3.10/dist-packages/streamlit/runtime/metrics_util.py\", line 358, in wrapped_func\n",
            "    result = non_optional_func(*args, **kwargs)\n",
            "  File \"/usr/local/lib/python3.10/dist-packages/streamlit/elements/widgets/file_uploader.py\", line 365, in file_uploader\n",
            "    return self._file_uploader(\n",
            "  File \"/usr/local/lib/python3.10/dist-packages/streamlit/elements/widgets/file_uploader.py\", line 451, in _file_uploader\n",
            "    widget_state = register_widget(\n",
            "  File \"/usr/local/lib/python3.10/dist-packages/streamlit/runtime/state/widgets.py\", line 161, in register_widget\n",
            "    return register_widget_from_metadata(metadata, ctx, widget_func_name, element_type)\n",
            "  File \"/usr/local/lib/python3.10/dist-packages/streamlit/runtime/state/widgets.py\", line 206, in register_widget_from_metadata\n",
            "    raise DuplicateWidgetID(\n",
            "streamlit.errors.DuplicateWidgetID: There are multiple identical `st.file_uploader` widgets with the\n",
            "same generated key.\n",
            "\n",
            "When a widget is created, it's assigned an internal key based on\n",
            "its structure. Multiple widgets with an identical structure will\n",
            "result in the same internal key, which causes this error.\n",
            "\n",
            "To fix this error, please pass a unique `key` argument to\n",
            "`st.file_uploader`.\n",
            "1/1 [==============================] - 1s 1s/step\n",
            "2023-08-30 14:41:51.678 Uncaught app exception\n",
            "Traceback (most recent call last):\n",
            "  File \"/usr/local/lib/python3.10/dist-packages/streamlit/runtime/scriptrunner/script_runner.py\", line 552, in _run_script\n",
            "    exec(code, module.__dict__)\n",
            "  File \"/content/drive/MyDrive/app4.py\", line 23, in <module>\n",
            "    accuracy = accuracy_score(y_test, y_pred)\n",
            "NameError: name 'accuracy_score' is not defined\n",
            "2023-08-30 14:42:24.573 Uncaught app exception\n",
            "Traceback (most recent call last):\n",
            "  File \"/usr/local/lib/python3.10/dist-packages/streamlit/runtime/scriptrunner/script_runner.py\", line 552, in _run_script\n",
            "    exec(code, module.__dict__)\n",
            "  File \"/content/drive/MyDrive/app4.py\", line 23, in <module>\n",
            "    accuracy = accuracy_score(y_test, y_pred)\n",
            "NameError: name 'y_test' is not defined\n",
            "2023-08-30 14:43:06.267 Uncaught app exception\n",
            "Traceback (most recent call last):\n",
            "  File \"/usr/local/lib/python3.10/dist-packages/streamlit/runtime/scriptrunner/script_runner.py\", line 552, in _run_script\n",
            "    exec(code, module.__dict__)\n",
            "  File \"/content/drive/MyDrive/app4.py\", line 23, in <module>\n",
            "    accuracy = accuracy_score(X,y)\n",
            "  File \"/usr/local/lib/python3.10/dist-packages/sklearn/utils/_param_validation.py\", line 192, in wrapper\n",
            "    return func(*args, **kwargs)\n",
            "  File \"/usr/local/lib/python3.10/dist-packages/sklearn/metrics/_classification.py\", line 221, in accuracy_score\n",
            "    y_type, y_true, y_pred = _check_targets(y_true, y_pred)\n",
            "  File \"/usr/local/lib/python3.10/dist-packages/sklearn/metrics/_classification.py\", line 95, in _check_targets\n",
            "    raise ValueError(\n",
            "ValueError: Classification metrics can't handle a mix of continuous-multioutput and multiclass targets\n",
            "2023-08-30 14:44:36.001 Uncaught app exception\n",
            "Traceback (most recent call last):\n",
            "  File \"/usr/local/lib/python3.10/dist-packages/streamlit/runtime/scriptrunner/script_runner.py\", line 552, in _run_script\n",
            "    exec(code, module.__dict__)\n",
            "  File \"/content/drive/MyDrive/app4.py\", line 18, in <module>\n",
            "    _train, X_test, y_train, y_test = train_test_split(X, y, test_size=0.2, random_state=42)\n",
            "NameError: name 'train_test_split' is not defined\n",
            "2023-08-30 14:44:57.541 Uncaught app exception\n",
            "Traceback (most recent call last):\n",
            "  File \"/usr/local/lib/python3.10/dist-packages/streamlit/runtime/scriptrunner/script_runner.py\", line 552, in _run_script\n",
            "    exec(code, module.__dict__)\n",
            "  File \"/content/drive/MyDrive/app4.py\", line 23, in <module>\n",
            "    model.fit(X_train, y_train)\n",
            "NameError: name 'X_train' is not defined\n",
            "2023-08-30 14:45:05.005 Uncaught app exception\n",
            "Traceback (most recent call last):\n",
            "  File \"/usr/local/lib/python3.10/dist-packages/streamlit/runtime/scriptrunner/script_runner.py\", line 552, in _run_script\n",
            "    exec(code, module.__dict__)\n",
            "  File \"/content/drive/MyDrive/app4.py\", line 23, in <module>\n",
            "    model.fit(X_train, y_train)\n",
            "NameError: name 'X_train' is not defined\n",
            "Accuracy: 100.00%\n",
            "2023-08-30 14:45:30.222 Uncaught app exception\n",
            "Traceback (most recent call last):\n",
            "  File \"/usr/local/lib/python3.10/dist-packages/streamlit/runtime/scriptrunner/script_runner.py\", line 552, in _run_script\n",
            "    exec(code, module.__dict__)\n",
            "  File \"/content/drive/MyDrive/app4.py\", line 35, in <module>\n",
            "    accuracy = accuracy_score(X,y)\n",
            "  File \"/usr/local/lib/python3.10/dist-packages/sklearn/utils/_param_validation.py\", line 192, in wrapper\n",
            "    return func(*args, **kwargs)\n",
            "  File \"/usr/local/lib/python3.10/dist-packages/sklearn/metrics/_classification.py\", line 221, in accuracy_score\n",
            "    y_type, y_true, y_pred = _check_targets(y_true, y_pred)\n",
            "  File \"/usr/local/lib/python3.10/dist-packages/sklearn/metrics/_classification.py\", line 95, in _check_targets\n",
            "    raise ValueError(\n",
            "ValueError: Classification metrics can't handle a mix of continuous-multioutput and multiclass targets\n",
            "2023-08-30 14:46:28.016 Uncaught app exception\n",
            "Traceback (most recent call last):\n",
            "  File \"/usr/local/lib/python3.10/dist-packages/streamlit/runtime/scriptrunner/script_runner.py\", line 552, in _run_script\n",
            "    exec(code, module.__dict__)\n",
            "  File \"/content/drive/MyDrive/app4.py\", line 23, in <module>\n",
            "    accuracy = accuracy_score(X,y)\n",
            "  File \"/usr/local/lib/python3.10/dist-packages/sklearn/utils/_param_validation.py\", line 192, in wrapper\n",
            "    return func(*args, **kwargs)\n",
            "  File \"/usr/local/lib/python3.10/dist-packages/sklearn/metrics/_classification.py\", line 221, in accuracy_score\n",
            "    y_type, y_true, y_pred = _check_targets(y_true, y_pred)\n",
            "  File \"/usr/local/lib/python3.10/dist-packages/sklearn/metrics/_classification.py\", line 95, in _check_targets\n",
            "    raise ValueError(\n",
            "ValueError: Classification metrics can't handle a mix of continuous-multioutput and multiclass targets\n",
            "\u001b[34m  Stopping...\u001b[0m\n",
            "^C\n"
          ]
        }
      ]
    },
    {
      "cell_type": "code",
      "source": [],
      "metadata": {
        "id": "uSx0PYzEo63y"
      },
      "execution_count": null,
      "outputs": []
    }
  ]
}